Workbook
Name Lista_AgentesVentas: Tabla_AgenteVentas[Agentes de ventas]
Name Lista_CategoríasVentas: Tabla_CategoríaVentas[Categorías de ventas]
Name Lista_FasesVentas: Tabla_FaseVentas[Fases de ventas]
Name Lista_RegionesVentas: Tabla_RegiónVentas[Regiones de ventas]
Name Mes_inicial: 'Previsión de ventas'!$C$5
Name NombreEmpresa: 'Entrada de previsión'!$B$2

Sheet Entrada de previsión
B2: HLP Manufacturing INC
B3: Previsión de ventas
B4: Confidencial
B6: SET URBAN CHILL | C6: MATERIAL | D6: COSTO | E6: total | G6: GASTOS MENSUALES | H6: COSTOS | I6: total
B7: Tela | C7: 150 metros cmt | D7: 9000 | E7: 21597 | G7: Banco | H7: 1500000 | I7: 19,720.000
B8: papel tinta | C8: 1 40 ctm | D8: 3000 | G8: Arriendo | H8: 1200000
B9: sublimacion | C9: 1 50 ctm | D9: 4500 | G9: Servicios | H9: 620000
B10: elastico | C10: 70 | D10: 327 | G10: Harry | H10: 800000
B11: hilos | D11: 500 | G11: Publicidad | H11: 3600000
B12: marquillas | C12: 2 | D12: 1000 | G12: Modelo | H12: 400000
B13: Bolsa normal | C13: 1 | D13: 70 | G13: Nomina | H13: 5600000
B14: Bolsa de lujo | C14: 1 | D14: 1200 | G14: Surtido | H14: 6000000
B15: Etiqueta | C15: 1 | D15: 2000
B18: ENTERIZO URBAN FLOW | C18: MATERIAL | D18: COSTO | E18: total
B19: Tela | C19: 1.70 ctm | D19: 9600 | E19: 21220
B20: papel tinta | C20: 1.40 ctm | D20: 3000
B21: sublimacion | C21: 1 70 ctm | D21: 5000
B22: hilos | C22: 1500 | D22: 1500
B23: marquillas | C23: 1 | D23: 50
B24: Bolsa normal | C24: 1 | D24: 70
B25: Bolsa de lujo | C25: 1 | D25: 1200
B26: Etiqueta | C26: 1 | D26: 200
B27: Borches | C27: 6 | D27: 600
B29: SET PREMIUM ESENCIAL | C29: MATERIAL | D29: COSTO | E29: TOTAL
B30: Tela | C30: 2 metros | D30: 12000 | E30: 25097
B31: papel tinta | C31: 1. 90 centimetros | D31: 3800
B32: sublimacion | C32: tela calandrada | D32: 5800
B33: hilos | D33: 500
B34: Broches | C34: 8 broches (botones) | D34: 600
B35: sesgo | C35: 2 tiras metros | D35: 500
B36: marquillas | C36: 2 marquillas | D36: 100
B37: Bolsa normal | C37: bolsa, bolsa del conjunto | D37: 70
B38: Elastico | C38: resorte | D38: 327
B39: Bolsa de lujo | C39: 1 | D39: 1200
B40: Etiqueta | C40: 1 | D40: 200
B44: SET PREMIUM ESENCIAL EN SHORT | C44: MATERIAL | D44: COSTO | E44: TOTAL
B45: Tela | C45: 1,20 ctm | D45: 8000 | E45: 19497
B46: papel tinta | C46: 1.50 ctm | D46: 3500
B47: sublimacion | C47: 1,50 ctm | D47: 4500
B48: hilos | D48: 500
...

Sheet Previsión de ventas
B2: =NombreEmpresa -> HLP Manufacturing INC
B3: Gráfico de previsión
B4: Confidencial
B5: Mes inicial | C5: =DATE(YEAR(TODAY())+1,1,1) -> 46023
B6: Mes | C6: Mensualmente previsión | D6: Acumulado | P6: =B6 -> Mes | Q6: Previsión mensual | R6: Acumulado
B7: =DATE(YEAR(Mes_inicial),MONTH(Mes_inicial)+0,1) -> 46023 | C7: =SUMIFS(Tabla_EntradaPrevisión[total],#REF!,">="&'Previsión de ventas'!B7,#REF!,"<="&DATE(YEAR('Previsión de ventas'!B7),MONTH('Previsión de ventas'!B7)+1,0)) -> #REF! | D7: =IF(ISNUMBER(D6),D6+C7,C7) -> #REF! | P7: =B7 -> 46023 | Q7: =C7 -> #REF! | R7: =D7-C7 -> #REF!
B8: =DATE(YEAR(Mes_inicial),MONTH(Mes_inicial)+1,1) -> 46054 | C8: =SUMIFS(Tabla_EntradaPrevisión[total],#REF!,">="&'Previsión de ventas'!B8,#REF!,"<="&DATE(YEAR('Previsión de ventas'!B8),MONTH('Previsión de ventas'!B8)+1,0)) -> #REF! | D8: =IF(ISNUMBER(D7),D7+C8,C8) -> #REF! | P8: =B8 -> 46054 | Q8: =C8 -> #REF! | R8: =D8-C8 -> #REF!
B9: =DATE(YEAR(Mes_inicial),MONTH(Mes_inicial)+2,1) -> 46082 | C9: =SUMIFS(Tabla_EntradaPrevisión[total],#REF!,">="&'Previsión de ventas'!B9,#REF!,"<="&DATE(YEAR('Previsión de ventas'!B9),MONTH('Previsión de ventas'!B9)+1,0)) -> #REF! | D9: =IF(ISNUMBER(D8),D8+C9,C9) -> #REF! | P9: =B9 -> 46082 | Q9: =C9 -> #REF! | R9: =D9-C9 -> #REF!
B10: =DATE(YEAR(Mes_inicial),MONTH(Mes_inicial)+3,1) -> 46113 | C10: =SUMIFS(Tabla_EntradaPrevisión[total],#REF!,">="&'Previsión de ventas'!B10,#REF!,"<="&DATE(YEAR('Previsión de ventas'!B10),MONTH('Previsión de ventas'!B10)+1,0)) -> #REF! | D10: =IF(ISNUMBER(D9),D9+C10,C10) -> #REF! | P10: =B10 -> 46113 | Q10: =C10 -> #REF! | R10: =D10-C10 -> #REF!
B11: =DATE(YEAR(Mes_inicial),MONTH(Mes_inicial)+4,1) -> 46143 | C11: =SUMIFS(Tabla_EntradaPrevisión[total],#REF!,">="&'Previsión de ventas'!B11,#REF!,"<="&DATE(YEAR('Previsión de ventas'!B11),MONTH('Previsión de ventas'!B11)+1,0)) -> #REF! | D11: =IF(ISNUMBER(D10),D10+C11,C11) -> #REF! | P11: =B11 -> 46143 | Q11: =C11 -> #REF! | R11: =D11-C11 -> #REF!
B12: =DATE(YEAR(Mes_inicial),MONTH(Mes_inicial)+5,1) -> 46174 | C12: =SUMIFS(Tabla_EntradaPrevisión[total],#REF!,">="&'Previsión de ventas'!B12,#REF!,"<="&DATE(YEAR('Previsión de ventas'!B12),MONTH('Previsión de ventas'!B12)+1,0)) -> #REF! | D12: =IF(ISNUMBER(D11),D11+C12,C12) -> #REF! | P12: =B12 -> 46174 | Q12: =C12 -> #REF! | R12: =D12-C12 -> #REF!
B13: =DATE(YEAR(Mes_inicial),MONTH(Mes_inicial)+6,1) -> 46204 | C13: =SUMIFS(Tabla_EntradaPrevisión[total],#REF!,">="&'Previsión de ventas'!B13,#REF!,"<="&DATE(YEAR('Previsión de ventas'!B13),MONTH('Previsión de ventas'!B13)+1,0)) -> #REF! | D13: =IF(ISNUMBER(D12),D12+C13,C13) -> #REF! | P13: =B13 -> 46204 | Q13: =C13 -> #REF! | R13: =D13-C13 -> #REF!
B14: =DATE(YEAR(Mes_inicial),MONTH(Mes_inicial)+7,1) -> 46235 | C14: =SUMIFS(Tabla_EntradaPrevisión[total],#REF!,">="&'Previsión de ventas'!B14,#REF!,"<="&DATE(YEAR('Previsión de ventas'!B14),MONTH('Previsión de ventas'!B14)+1,0)) -> #REF! | D14: =IF(ISNUMBER(D13),D13+C14,C14) -> #REF! | P14: =B14 -> 46235 | Q14: =C14 -> #REF! | R14: =D14-C14 -> #REF!
B15: =DATE(YEAR(Mes_inicial),MONTH(Mes_inicial)+8,1) -> 46266 | C15: =SUMIFS(Tabla_EntradaPrevisión[total],#REF!,">="&'Previsión de ventas'!B15,#REF!,"<="&DATE(YEAR('Previsión de ventas'!B15),MONTH('Previsión de ventas'!B15)+1,0)) -> #REF! | D15: =IF(ISNUMBER(D14),D14+C15,C15) -> #REF! | P15: =B15 -> 46266 | Q15: =C15 -> #REF! | R15: =D15-C15 -> #REF!
B16: =DATE(YEAR(Mes_inicial),MONTH(Mes_inicial)+9,1) -> 46296 | C16: =SUMIFS(Tabla_EntradaPrevisión[total],#REF!,">="&'Previsión de ventas'!B16,#REF!,"<="&DATE(YEAR('Previsión de ventas'!B16),MONTH('Previsión de ventas'!B16)+1,0)) -> #REF! | D16: =IF(ISNUMBER(D15),D15+C16,C16) -> #REF! | P16: =B16 -> 46296 | Q16: =C16 -> #REF! | R16: =D16-C16 -> #REF!
B17: =DATE(YEAR(Mes_inicial),MONTH(Mes_inicial)+10,1) -> 46327 | C17: =SUMIFS(Tabla_EntradaPrevisión[total],#REF!,">="&'Previsión de ventas'!B17,#REF!,"<="&DATE(YEAR('Previsión de ventas'!B17),MONTH('Previsión de ventas'!B17)+1,0)) -> #REF! | D17: =IF(ISNUMBER(D16),D16+C17,C17) -> #REF! | P17: =B17 -> 46327 | Q17: =C17 -> #REF! | R17: =D17-C17 -> #REF!
B18: =DATE(YEAR(Mes_inicial),MONTH(Mes_inicial)+11,1) -> 46357 | C18: =SUMIFS(Tabla_EntradaPrevisión[total],#REF!,">="&'Previsión de ventas'!B18,#REF!,"<="&DATE(YEAR('Previsión de ventas'!B18),MONTH('Previsión de ventas'!B18)+1,0)) -> #REF! | D18: =IF(ISNUMBER(D17),D17+C18,C18) -> #REF! | P18: =B18 -> 46357 | Q18: =C18 -> #REF! | R18: =D18-C18 -> #REF!

Sheet Listas
B2: =NombreEmpresa -> HLP Manufacturing INC
B3: Listas de ventas
B4: Confidencial
B6: Agentes de ventas | C6: Regiones de ventas | D6: Categorías de ventas | E6: Fases de ventas
B7: Rowan Murphy | C7: Estados Unidos: nordeste | D7: Consultoría | E7: Necesidad identificada
B8: Miho Kojima | C8: Estados Unidos: sudeste | D8: Mezcla | E8: Oportunidad
B9: Cora Thomas | C9: Estados Unidos: norte central | D9: Productos | E9: Análisis de necesidades
B10: Ellis Turner | C10: Estados Unidos: sur central | D10: Servicios profesionales | E10: Solución propuesta
B11: Suma Kini | C11: Estados Unidos: noroeste | D11: Servicios | E11: Propuesta escrita
C12: Estados Unidos: sudoeste | D12: Soporte técnico | E12: Aprobación verbal
C13: Canadá: este | D13: Entrenamiento | E13: Aprobación formal
C14: Canadá: oeste | E14: Presupuesto validado
C15: EMEA: Francia | E15: Patrocinio
C16: EMEA: Alemania
C17: EMEA: Italia
C18: EMEA: otro
C19: APSA: Asia
C20: APSA: Pacífico
C21: APSA: México
C22: APSA: Australia
C23: APSA: otro
C24: EMEA: Reino Unido

Sheet Hoja1
