Workbook

Sheet Items PRUEBA VTAS
D2: DESTINO | E2: NACIONAL
D3: LISTA DE PRECIOS | E3: 002
D4: DESCUENTO % | E4: 0.15
D5: FLETE APROXIMADO | E5: A definir
B6: Producto / Presentacion | C6: TOP VENTAS | D6: Laboratorio | E6: E-COMME. | F6: Precio distribuidor | G6: Ganancia bodega | H6: Ingreso x mesBodega | I6: Costo envio | J6: Margen40% | K6: Precio final | L6: Rotacion x mes | M6: Ingresos x mes Productopolis | N6: Precio Mercado | O6: Con envio | P6: Dif. Vs Productopolis
A7: 20 | B7: FERTILIDAD MASCULINA FOB AUTOTEST NEWFOUNDLAND CASETE UNIDAD | C7: si | D7: NEWFOUNDLAND | E7: 86000 | F7: 59800 | G7: 26200 | H7: 131000 | I7: 12000 | J7: 120400 | K7: 132400 | L7: 5 | M7: 602000 | N7: 86000 | O7: 95000 | P7: -37400
A8: 27 | B8: MENOPAUSIA FSH AUTOTEST NEWFOUNDLAND MIDSTREAM UNIDAD | C8: si | D8: NEWFOUNDLAND | E8: 69000 | F8: 47900 | G8: 21100 | H8: 105500 | I8: 12000 | J8: 96600 | K8: 108600 | L8: 5 | M8: 483000 | N8: 69000 | O8: 78000 | P8: -30600
A9: 29 | B9: OVULACION LH AUTOTEST NEWFOUNDLAND MIDSTREAM UNIDAD | C9: si | D9: NEWFOUNDLAND | E9: 67000 | F9: 46500 | G9: 20500 | H9: 102500 | I9: 12000 | J9: 93800 | K9: 105800 | L9: 5 | M9: 469000 | N9: 67000 | O9: 76000 | P9: -29800
A10: 39 | B10: SALUD RENAL MAU AUTOTEST NEWFOUNDLAND MIDSTREAM UNIDAD | C10: si | D10: NEWFOUNDLAND | E10: 62000 | F10: 43200 | G10: 18800 | H10: 94000 | I10: 12000 | J10: 86800 | K10: 98800 | L10: 5 | M10: 434000 | N10: 62000 | O10: 71000 | P10: -27800
A11: 41 | B11: SUPER MEGA GAINER VAINILLA IMPORTADO GMN POLVO X 2 LB | C11: si | D11: GMN | E11: 60000 | F11: 41900 | G11: 18100 | H11: 90500 | I11: 12000 | J11: 84000 | K11: 96000 | L11: 5 | M11: 420000 | N11: 70780 | O11: 79780 | P11: -16220
A12: 42 | B12: DEFICIENCIA HIERRO FERRITINA AUTOTEST NEWFOUNDLAND CASETE UNIDAD | C12: si | D12: NEWFOUNDLAND | E12: 59000 | F12: 41200 | G12: 17800 | H12: 89000 | I12: 12000 | J12: 82600 | K12: 94600 | L12: 5 | M12: 413000 | N12: 59000 | O12: 68000 | P12: -26600
A13: 43 | B13: DEFICIENCIA VITAMINA D AUTOTEST NEWFOUNDLAND CASETE UNIDAD | C13: si | D13: NEWFOUNDLAND | E13: 59000 | F13: 41200 | G13: 17800 | H13: 89000 | I13: 12000 | J13: 82600 | K13: 94600 | L13: 5 | M13: 413000 | N13: 59000 | O13: 68000 | P13: -26600
A14: 64 | B14: FIBERLAB (FIBRA DIETARIA) NARANJA PHARBIOLAB® POLVO X 1000 G | C14: si | D14: PHARBIOLAB® | E14: 43000 | F14: 30000 | G14: 13000 | H14: 65000 | I14: 12000 | J14: 60200 | K14: 72200 | L14: 5 | M14: 301000 | N14: 60900 | O14: 69900 | P14: -2300
A15: 65 | B15: GELILAB ADVANCE (COLAGENO HIDROL.) UVA PHARBIOLAB® POLVO X 1000 G | C15: si | D15: PHARBIOLAB® | E15: 43000 | F15: 30000 | G15: 13000 | H15: 65000 | I15: 12000 | J15: 60200 | K15: 72200 | L15: 5 | M15: 301000 | N15: 60900 | O15: 69900 | P15: -2300
A16: 68 | B16: SURELAB ULTRA (MULTIVITAMINICO) VAINILLA PHARBIOLAB® POLVO X 1000 G | C16: si | D16: PHARBIOLAB® | E16: 43000 | F16: 30000 | G16: 13000 | H16: 65000 | I16: 12000 | J16: 60200 | K16: 72200 | L16: 5 | M16: 301000 | N16: 60900 | O16: 69900 | P16: -2300
A17: 94 | B17: CITRATO DE MAGNESIO 900 MG + VIT. C 600 MG GENESIS X 90 CAPSULAS | C17: si | D17: GENESIS | E17: 37000 | F17: 25800 | G17: 11200 | H17: 56000 | I17: 12000 | J17: 51800 | K17: 63800 | L17: 5 | M17: 259000 | N17: 57900 | O17: 66900 | P17: 3100
A18: 95 | B18: CITRATO DE POTASIO 750 MG + CITRATO DE MAGNESIO 750 MG GENESIS X 90 CAPSULAS | C18: si | D18: GENESIS | E18: 37000 | F18: 25800 | G18: 11200 | H18: 56000 | I18: 12000 | J18: 51800 | K18: 63800 | L18: 5 | M18: 259000 | N18: 83850 | O18: 92850 | P18: 29050
... A29: 124 | B29: POWERS'X NATURALPOWER SOBRE X 4 TABLETAS | C29: si | D29: NATURAL POWER | E29: 3000 | F29: 1900 | G29: 1100 | H29: 5500 | I29: 12000 | J29: 4200 | K29: 16200 | L29: 5 | M29: 21000 | N29: 24000 | O29: 33000 | P29: 16800
A30: 128 | B30: VIH AUTOTEST NEWFOUNDLAND MIDSTREAM UNIDAD | C30: si | D30: NEWFOUNDLAND | E30: 0 | F30: 0 | G30: 0 | H30: 0 | I30: 12000 | J30: 0 | K30: 12000 | L30: 5 | M30: 0
D32: INGRESOS BRUTOS | H32: =SUM(H7:H31) -> 1295000 | M32: =SUM(M7:M31) -> 5929000

Sheet Analisis Margen
D2: DESTINO | E2: NACIONAL
D3: LISTA DE PRECIOS | E3: 002
D4: DESCUENTO % | E4: 0.15
D5: FLETE APROXIMADO | E5: A definir
B6: Producto / Presentacion | C6: TOP VENTAS | D6: Laboratorio | E6: E-COMME. | F6: Precio distribuidor | G6: Ganancia bodega | H6: Ingreso x mesBodega | I6: Costo envio | J6: Margen40% | K6: Precio final | L6: Rotacion x mes | M6: Ingresos x mes | N6: Precio Mercado | O6: Con envio | P6: Dif. Vs Productopolis
A7: =+A6+1 -> 1 | B7: POWERS'X NATURALPOWER BOLSA X 100 SOBRES X 400 TABLETAS | D7: NATURAL POWER | E7: 243000 | F7: =+VLOOKUP(B7,Distribuidor!$B$7:$D$533,3,0) -> 170000 | G7: =+E7-F7 -> 73000 | I7: 12000 | J7: =+E7*1.4 -> 340200 | K7: =+J7+I7 -> 352200
A8: =+A7+1 -> 2 | B8: GENGI FRESH PASTILLAS MANA BOMBONERA X 60 SOBRES | D8: EL MANA | E8: 229000 | F8: =+VLOOKUP(B8,Distribuidor!$B$7:$D$533,3,0) -> 160000 | G8: =+E8-F8 -> 69000 | I8: 12000 | J8: =+E8*1.4 -> 320600 | K8: =+J8+I8 -> 332600
A9: =+A8+1 -> 3 | B9: THOR MEGA MASS GAINER VAINILLA MASS PROTEINS POLVO X 13 LB | D9: NATURAL LIFE | E9: 194000 | F9: =+VLOOKUP(B9,Distribuidor!$B$7:$D$533,3,0) -> 135400 | G9: =+E9-F9 -> 58600 | I9: 12000 | J9: =+E9*1.4 -> 271600 | K9: =+J9+I9 -> 283600
A10: =+A9+1 -> 4 | B10: MEGAS'X AZUL NATURALPOWER BOLSA X 100 PASTILLEROS X 300 TABLETAS | D10: NATURAL POWER | E10: 186000 | F10: =+VLOOKUP(B10,Distribuidor!$B$7:$D$533,3,0) -> 130000 | G10: =+E10-F10 -> 56000 | I10: 12000 | J10: =+E10*1.4 -> 260400 | K10: =+J10+I10 -> 272400
A11: =+A10+1 -> 5 | B11: THERA WHEY (PROTEINA LIMPIA) VAINILLA NATURAL LIGHT POLVO X 2 LB | D11: NATURAL LIGHT | E11: 152000 | F11: =+VLOOKUP(B11,Distribuidor!$B$7:$D$533,3,0) -> 106400 | G11: =+E11-F11 -> 45600 | I11: 12000 | J11: =+E11*1.4 -> 212800 | K11: =+J11+I11 -> 224800
A12: =+A11+1 -> 6 | B12: BRONQUISAN PASTILLAS MANA BOMBONERA X 60 SOBRES | D12: EL MANA | E12: 143000 | F12: =+VLOOKUP(B12,Distribuidor!$B$7:$D$533,3,0) -> 100000 | G12: =+E12-F12 -> 43000 | I12: 12000 | J12: =+E12*1.4 -> 200200 | K12: =+J12+I12 -> 212200
A13: =+A12+1 -> 7 | B13: MEGA GAINER VAINILLA IMPORTADO GMN POLVO X 5 LB | D13: GMN | E13: 132000 | F13: =+VLOOKUP(B13,Distribuidor!$B$7:$D$533,3,0) -> 92200 | G13: =+E13-F13 -> 39800 | I13: 12000 | J13: =+E13*1.4 -> 184800 | K13: =+J13+I13 -> 196800
A14: =+A13+1 -> 8 | B14: SUPER MEGA GAINER VAINILLA IMPORTADO GMN POLVO X 5 LB | D14: GMN | E14: 132000 | F14: =+VLOOKUP(B14,Distribuidor!$B$7:$D$533,3,0) -> 92200 | G14: =+E14-F14 -> 39800 | I14: 12000 | J14: =+E14*1.4 -> 184800 | K14: =+J14+I14 -> 196800
A15: =+A14+1 -> 9 | B15: RAPTOR CARNICA FRUTOS ROJOS MASS PROTEINS POLVO X 3 LB | D15: NATURAL LIFE | E15: 126000 | F15: =+VLOOKUP(B15,Distribuidor!$B$7:$D$533,3,0) -> 88000 | G15: =+E15-F15 -> 38000 | I15: 12000 | J15: =+E15*1.4 -> 176400 | K15: =+J15+I15 -> 188400
A16: =+A15+1 -> 10 | B16: SUPREME CREATINA CEREZA IMPORTADO GMN POLVO X 450 G | D16: GMN | E16: 114000 | F16: =+VLOOKUP(B16,Distribuidor!$B$7:$D$533,3,0) -> 79500 | G16: =+E16-F16 -> 34500 | I16: 12000 | J16: =+E16*1.4 -> 159600 | K16: =+J16+I16 -> 171600
A17: =+A16+1 -> 11 | B17: SUPREME CREATINA CITRUS PUNCH IMPORTADO GMN POLVO X 450 G | D17: GMN | E17: 114000 | F17: =+VLOOKUP(B17,Distribuidor!$B$7:$D$533,3,0) -> 79500 | G17: =+E17-F17 -> 34500 | I17: 12000 | J17: =+E17*1.4 -> 159600 | K17: =+J17+I17 -> 171600
A18: =+A17+1 -> 12 | B18: SUPREME CREATINA MANGO BICHE IMPORTADO GMN POLVO X 450 G | D18: GMN | E18: 114000 | F18: =+VLOOKUP(B18,Distribuidor!$B$7:$D$533,3,0) -> 79500 | G18: =+E18-F18 -> 34500 | I18: 12000 | J18: =+E18*1.4 -> 159600 | K18: =+J18+I18 -> 171600
A19: =+A18+1 -> 13 | B19: DETECCION DENGUE NSL AUTOTEST NEWFOUNDLAND CASETE UNIDAD | C19: si | D19: NEWFOUNDLAND | E19: 98000 | F19: =+VLOOKUP(B19,Distribuidor!$B$7:$D$533,3,0) -> 68100 | G19: =+E19-F19 -> 29900 | H19: =+G19*L19 -> 149500 | I19: 12000 | J19: =+E19*1.4 -> 137200 | K19: =+J19+I19 -> 149200 | L19: 5 | M19: =+J19*L19 -> 686000 | N19: =+E19 -> 98000 | O19: =9000+N19 -> 107000 | P19: =+O19-K19 -> -42200
A20: =+A19+1 -> 14 | B20: KIT KERATIN (SHAMPOO 400 ML + ACONDIC. 400 ML + LOCION 320 ML) Mª SALOME | D20: MARIA SALOME | E20: 97000 | F20: =+VLOOKUP(B20,Distribuidor!$B$7:$D$533,3,0) -> 67700 | G20: =+E20-F20 -> 29300 | I20: 12000 | J20: =+E20*1.4 -> 135800 | K20: =+J20+I20 -> 147800
A21: =+A20+1 -> 15 | B21: FORCE CREATINE MASS PROTEINS POLVO X 450 G | D21: NATURAL LIFE | E21: 97000 | F21: =+VLOOKUP(B21,Distribuidor!$B$7:$D$533,3,0) -> 67700 | G21: =+E21-F21 -> 29300 | I21: 12000 | J21: =+E21*1.4 -> 135800 | K21: =+J21+I21 -> 147800
A22: =+A21+1 -> 16 | B22: NITRO MASS VAINILLA IMPORTADO GMN POLVO X 2 LB | D22: GMN | E22: 94000 | F22: =+VLOOKUP(B22,Distribuidor!$B$7:$D$533,3,0) -> 65200 | G22: =+E22-F22 -> 28800 | I22: 12000 | J22: =+E22*1.4 -> 131600 | K22: =+J22+I22 -> 143600
A23: =+A22+1 -> 17 | B23: SALUD PROSTATICA PSA AUTOTEST NEWFOUNDLAND CASETE UNIDAD | C23: si | D23: NEWFOUNDLAND | E23: 93000 | F23: =+VLOOKUP(B23,Distribuidor!$B$7:$D$533,3,0) -> 65100 | G23: =+E23-F23 -> 27900 | H23: =+G23*L23 -> 139500 | I23: 12000 | J23: =+E23*1.4 -> 130200 | K23: =+J23+I23 -> 142200 | L23: 5 | M23: =+J23*L23 -> 651000 | N23: =+E23 -> 93000 | O23: =9000+N23 -> 102000 | P23: =+O23-K23 -> -40200
A24: =+A23+1 -> 18 | B24: BODY RIPPED VAINILLA IMPORTADO GMN POLVO X 2 LB | D24: GMN | E24: 91000 | F24: =+VLOOKUP(B24,Distribuidor!$B$7:$D$533,3,0) -> 63700 | G24: =+E24-F24 -> 27300 | I24: 12000 | J24: =+E24*1.4 -> 127400 | K24: =+J24+I24 -> 139400
A25: =+A24+1 -> 19 | B25: KIT TRADICIONAL (SHAMPOO 400 ML + ACONDIC. 400 ML + LOCION 320 ML) Mª SALOME | D25: MARIA SALOME | E25: 89000 | F25: =+VLOOKUP(B25,Distribuidor!$B$7:$D$533,3,0) -> 62200 | G25: =+E25-F25 -> 26800 | I25: 12000 | J25: =+E25*1.4 -> 124600 | K25: =+J25+I25 -> 136600
A26: =+A25+1 -> 20 | B26: FERTILIDAD MASCULINA FOB AUTOTEST NEWFOUNDLAND CASETE UNIDAD | C26: si | D26: NEWFOUNDLAND | E26: 86000 | F26: =+VLOOKUP(B26,Distribuidor!$B$7:$D$533,3,0) -> 59800 | G26: =+E26-F26 -> 26200 | H26: =+G26*L26 -> 131000 | I26: 12000 | J26: =+E26*1.4 -> 120400 | K26: =+J26+I26 -> 132400 | L26: 5 | M26: =+J26*L26 -> 602000 | N26: =+E26 -> 86000 | O26: =9000+N26 -> 95000 | P26: =+O26-K26 -> -37400
A27: =+A26+1 -> 21 | B27: ATOMIC PREWORKOUT FRUTOS ROJOS MASS PROTEINS POLVO X 450 G | D27: NATURAL LIFE | E27: 78000 | F27: =+VLOOKUP(B27,Distribuidor!$B$7:$D$533,3,0) -> 54200 | G27: =+E27-F27 -> 23800 | I27: 12000 | J27: =+E27*1.4 -> 109200 | K27: =+J27+I27 -> 121200
A28: =+A27+1 -> 22 | B28: THUNDER L-GLUTAMINE FRUTOS AMARILLOS MASS PROTEINS POLVO X 450 G | D28: NATURAL LIFE | E28: 78000 | F28: =+VLOOKUP(B28,Distribuidor!$B$7:$D$533,3,0) -> 54200 | G28: =+E28-F28 -> 23800 | I28: 12000 | J28: =+E28*1.4 -> 109200 | K28: =+J28+I28 -> 121200
A29: =+A28+1 -> 23 | B29: SALUD INTESTINAL FOB AUTOTEST NEWFOUNDLAND CASETE UNIDAD | C29: si | D29: NEWFOUNDLAND | E29: 73000 | F29: =+VLOOKUP(B29,Distribuidor!$B$7:$D$533,3,0) -> 50500 | G29: =+E29-F29 -> 22500 | H29: =+G29*L29 -> 112500 | I29: 12000 | J29: =+E29*1.4 -> 102200 | K29: =+J29+I29 -> 114200 | L29: 5 | M29: =+J29*L29 -> 511000 | N29: =+E29 -> 73000 | O29: =9000+N29 -> 82000 | P29: =+O29-K29 -> -32200
A30: =+A29+1 -> 24 | B30: TIROIDES TSH AUTOTEST NEWFOUNDLAND CASETE UNIDAD | C30: si | D30: NEWFOUNDLAND | E30: 73000 | F30: =+VLOOKUP(B30,Distribuidor!$B$7:$D$533,3,0) -> 50500 | G30: =+E30-F30 -> 22500 | H30: =+G30*L30 -> 112500 | I30: 12000 | J30: =+E30*1.4 -> 102200 | K30: =+J30+I30 -> 114200 | L30: 5 | M30: =+J30*L30 -> 511000 | N30: =+E30 -> 73000 | O30: =9000+N30 -> 82000 | P30: =+O30-K30 -> -32200
A31: =+A30+1 -> 25 | B31: ULCERA ESTOMACAL H. PYLORI AUTOTEST NEWFOUNDLAND CASETE UNIDAD | C31: si | D31: NEWFOUNDLAND | E31: 73000 | F31: =+VLOOKUP(B31,Distribuidor!$B$7:$D$533,3,0) -> 50500 | G31: =+E31-F31 -> 22500 | H31: =+G31*L31 -> 112500 | I31: 12000 | J31: =+E31*1.4 -> 102200 | K31: =+J31+I31 -> 114200 | L31: 5 | M31: =+J31*L31 -> 511000 | N31: =+E31 -> 73000 | O31: =9000+N31 -> 82000 | P31: =+O31-K31 -> -32200
A32: =+A31+1 -> 26 | B32: SUTRA (POTENCIADOR) GENESIS DISPLAY X 30 SACHETS | D32: GENESIS | E32: 72000 | F32: =+VLOOKUP(B32,Distribuidor!$B$7:$D$533,3,0) -> 50000 | G32: =+E32-F32 -> 22000 | I32: 12000 | J32: =+E32*1.4 -> 100800 | K32: =+J32+I32 -> 112800
A33: =+A32+1 -> 27 | B33: MENOPAUSIA FSH AUTOTEST NEWFOUNDLAND MIDSTREAM UNIDAD | C33: si | D33: NEWFOUNDLAND | E33: 69000 | F33: =+VLOOKUP(B33,Distribuidor!$B$7:$D$533,3,0) -> 47900 | G33: =+E33-F33 -> 21100 | H33: =+G33*L33 -> 105500 | I33: 12000 | J33: =+E33*1.4 -> 96600 | K33: =+J33+I33 -> 108600 | L33: 5 | M33: =+J33*L33 -> 483000 | N33: =+E33 -> 69000 | O33: =9000+N33 -> 78000 | P33: =+O33-K33 -> -30600
A34: =+A33+1 -> 28 | B34: THOR MEGA MASS GAINER VAINILLA MASS PROTEINS POLVO X 3,5 LB | D34: NATURAL LIFE | E34: 68000 | F34: =+VLOOKUP(B34,Distribuidor!$B$7:$D$533,3,0) -> 47400 | G34: =+E34-F34 -> 20600 | I34: 12000 | J34: =+E34*1.4 -> 95200 | K34: =+J34+I34 -> 107200
A35: =+A34+1 -> 29 | B35: OVULACION LH AUTOTEST NEWFOUNDLAND MIDSTREAM UNIDAD | C35: si | D35: NEWFOUNDLAND | E35: 67000 | F35: =+VLOOKUP(B35,Distribuidor!$B$7:$D$533,3,0) -> 46500 | G35: =+E35-F35 -> 20500 | H35: =+G35*L35 -> 102500 | I35: 12000 | J35: =+E35*1.4 -> 93800 | K35: =+J35+I35 -> 105800 | L35: 5 | M35: =+J35*L35 -> 469000 | N35: =+E35 -> 67000 | O35: =9000+N35 -> 76000 | P35: =+O35-K35 -> -29800
A36: =+A35+1 -> 30 | B36: COLAGENO MARINO HIDRO. + BIOTINA + VIT. E VAINILLA VITAMIN & LINE POLVO X 1000 G | D36: VITAMIN & LINE | E36: 66000 | F36: =+VLOOKUP(B36,Distribuidor!$B$7:$D$533,3,0) -> 46200 | G36: =+E36-F36 -> 19800 | I36: 12000 | J36: =+E36*1.4 -> 92400 | K36: =+J36+I36 -> 104400
A37: =+A36+1 -> 31 | B37: RESPIRIN GRIPA (ANTI-GRIPAL) SANLY DISPLAY X 10 BLISTER X 100 CAPSULAS | D37: SANLY | E37: 65000 | F37: =+VLOOKUP(B37,Distribuidor!$B$7:$D$533,3,0) -> 45000 | G37: =+E37-F37 -> 20000 | I37: 12000 | J37: =+E37*1.4 -> 91000 | K37: =+J37+I37 -> 103000
A38: =+A37+1 -> 32 | B38: MELATONINA 3 MG IMPORTADO VITAMIN & LINE X 100 SOFTGELS | D38: VITAMIN & LINE | E38: 64000 | F38: =+VLOOKUP(B38,Distribuidor!$B$7:$D$533,3,0) -> 44300 | G38: =+E38-F38 -> 19700 | I38: 12000 | J38: =+E38*1.4 -> 89600 | K38: =+J38+I38 -> 101600
A39: =+A38+1 -> 33 | B39: EXTREME MEGA MASS GAINER VAINILLA MASS PROTEINS POLVO X 3 LB | D39: NATURAL LIFE | E39: 63000 | F39: =+VLOOKUP(B39,Distribuidor!$B$7:$D$533,3,0) -> 44000 | G39: =+E39-F39 -> 19000 | I39: 12000 | J39: =+E39*1.4 -> 88200 | K39: =+J39+I39 -> 100200
A40: =+A39+1 -> 34 | B40: BIOTINA 900 MCG VITAMINE & LINE X 100 SOFTGELS | D40: VITAMIN & LINE | E40: 63000 | F40: =+VLOOKUP(B40,Distribuidor!$B$7:$D$533,3,0) -> 43700 | G40: =+E40-F40 -> 19300 | I40: 12000 | J40: =+E40*1.4 -> 88200 | K40: =+J40+I40 -> 100200
A41: =+A40+1 -> 35 | B41: COLAGENO MARINO CON PEPTIDOS UVA 3Q DISPLAY X 30 SACHETS | D41: VARIOS | E41: 63000 | F41: =+VLOOKUP(B41,Distribuidor!$B$7:$D$533,3,0) -> 43500 | G41: =+E41-F41 -> 19500 | I41: 12000 | J41: =+E41*1.4 -> 88200 | K41: =+J41+I41 -> 100200
...

Sheet TOP VENTAS
A1: Posicion | B1: Item | C1: TOP
A2: 1 | B2: POWERS'X NATURALPOWER SOBRE X 4 TABLETAS | C2: si
A3: =1+A2 -> 2 | B3: MEGAS'X AZUL NATURALPOWER PASTILLERO X 3 | C3: si
A4: =1+A3 -> 3 | B4: BRONQUISAN ADULTOS MANA JALEA X 240 ML | C4: si
A5: =1+A4 -> 4 | B5: BRONQUISAN KIDS MANA JALEA X 240 ML | C5: si
A6: =1+A5 -> 5 | B6: COMPLEJO B + ZINC + VITAMINA D3 PHARBIOL | C6: si
A7: =1+A6 -> 6 | B7: GELILAB ADVANCE (COLAGENO HIDROL.) UVA P | C7: si
A8: =1+A7 -> 7 | B8: SURELAB ULTRA (MULTIVITAMINICO) VAINILLA | C8: si
A9: =1+A8 -> 8 | B9: CITRATO DE MAGNESIO 900 MG + VIT. C 600 | C9: si
A10: =1+A9 -> 9 | B10: RAIZAN FLOMECOL JARABE X 330 ML | C10: si
A11: =1+A10 -> 10 | B11: VINAGRE DE CIDRA - MANZANA CAR&MER X 750 | C11: si
A12: =1+A11 -> 11 | B12: BRONCOX MAXX IMPROFARME JARABE X 120 ML | C12: si
A13: =1+A12 -> 12 | B13: ESENCIAS FLORALES STRES, DEPRESION, INSO | C13: si
A14: =1+A13 -> 13 | B14: AGUA DE COCO ELECTROLITOS BIOEIWA X 500 | C14: si
... A38: =1+A37 -> 37 | B38: SAVITOSITO VITALFARMA JARABE X 120 ML | C38: si
A39: =1+A38 -> 38 | B39: VINAGRE DE MANZANA CON LA MADRE GALLO X | C39: si | D39: no sale
A40: =1+A39 -> 39 | B40: CLORURO DE MAGNESIO IMPROFARME X 90 CAPS | C40: si
A41: 40 | B41: VINAGRE DE MANZANA - MIEL LA ESPERANZA X500 | C41: si | D41: no sale

Sheet Distribuidor
C2: DESTINO | D2: VERIFICAR
C3: LISTA DE PRECIOS | D3: 005
C4: DESCUENTO % | D4: 0
C5: FLETE APROXIMADO | D5: 0 - 20.000
B6: Producto / Presentacion | C6: Laboratorio | D6: TIENDA N.
B7: ACEITE DE AGUACATE ADRIANGEL X 120 ML | C7: ADRIANGEL | D7: 10000
B8: ACEITE DE AJONJOLI ADRIANGEL X 120 ML | C8: ADRIANGEL | D8: 10000
B9: ACEITE DE ALMENDRAS ADRIANGEL X 120 ML | C9: ADRIANGEL | D9: 10000
B10: ACEITE DE ARGAN SPRAY ADRIANGEL X 50 ML | C10: ADRIANGEL | D10: 21900
B11: ACEITE DE CAFE VERDE ADRIANGEL X 120 ML | C11: ADRIANGEL | D11: 10000
B12: ACEITE DE CALENDULA ADRIANGEL X 120 ML | C12: ADRIANGEL | D12: 10000
B13: ACEITE DE CANELA ADRIANGEL X 120 ML | C13: ADRIANGEL | D13: 10000
B14: ACEITE DE COCO ADRIANGEL X 120 ML | C14: ADRIANGEL | D14: 10000
B15: ACEITE DE EUCALIPTO ADRIANGEL X 120 ML | C15: ADRIANGEL | D15: 10000
B16: ACEITE DE GERMEN DE TRIGO ADRIANGEL X 120 ML | C16: ADRIANGEL | D16: 10000
B17: ACEITE DE GIRASOL ADRIANGEL X 120 ML | C17: ADRIANGEL | D17: 10200
B18: ACEITE DE JOJOBA ADRIANGEL X 120 ML | C18: ADRIANGEL | D18: 10000
... B412: ULCERA ESTOMACAL H. PYLORI AUTOTEST NEWFOUNDLAND CASETE UNIDAD | C412: NEWFOUNDLAND | D412: 50500
B413: VIH AUTOTEST NEWFOUNDLAND MIDSTREAM UNIDAD | C413: NEWFOUNDLAND
B414: CREMA POWER SENSATION COLAGENO NISSI DISPLAY X 12 SACHETS | C414: NISSI | D414: 11500
B415: CREMA POWER SENSATION COLAGENO NISSI X 750 ML | C415: NISSI | D415: 12900
B416: PROTECTOR SOLAR SUNWAY PLUS 50FPS NISSI DISPLAY X 12 SACHETS | C416: NISSI | D416: 20000
B417: PROTECTOR SOLAR SUNWAY PLUS 50FPS NISSI TUBO X 120 G | C417: NISSI | D417: 20000
B418: REPELENTE PICA FIN NISSI JABON BARRA X 50 G | C418: NISSI | D418: 9300
B419: REPELENTE PICA FIN NISSI ROLL ON X 50 ML | C419: NISSI | D419: 7900
B420: REPELENTE PICA FIN NISSI SPRAY X 120 ML | C420: NISSI | D420: 11500
B421: COLAGENO + BIOTINA PHARBIOLAB® BLISTER X 30 SOFTGELS | C421: PHARBIOLAB® | D421: 18000
B422: COLAGENO + BIOTINA PHARBIOLAB® FRASCO X 60 SOFTGELS | C422: PHARBIOLAB® | D422: 32000
B423: COMPLEJO B + ZINC + VITAMINA D3 PHARBIOLAB® BLISTER X 30 SOFTGELS | C423: PHARBIOLAB® | D423: 17200
B424: FIBERLAB (FIBRA DIETARIA) NARANJA PHARBIOLAB® POLVO X 1000 G | C424: PHARBIOLAB® | D424: 30000
B425: GELILAB ADVANCE (COLAGENO HIDROL.) UVA PHARBIOLAB® POLVO X 1000 G | C425: PHARBIOLAB® | D425: 30000
... B533: VITAMINA E 1000 UI + SELENIO IMPORTADO FARNAT BLISTER X 30 SOFTGELS | C533: VARIOS | D533: 19900
B536: PRODUCTO A DESCODIFICAR
B537: PRODUCTO SIN REGISTRO

Sheet Full Inventario
C2: DESTINO | D2: NACIONAL
C3: LISTA DE PRECIOS | D3: 002
C4: DESCUENTO % | D4: 0.15
C5: FLETE APROXIMADO | D5: A definir
B6: Producto / Presentacion | C6: Laboratorio | D6: E-COMME.
B7: ACEITE DE AGUACATE ADRIANGEL X 120 ML | C7: ADRIANGEL | D7: 15000
B8: ACEITE DE AJONJOLI ADRIANGEL X 120 ML | C8: ADRIANGEL | D8: 15000
B9: ACEITE DE ALMENDRAS ADRIANGEL X 120 ML | C9: ADRIANGEL | D9: 15000
B10: ACEITE DE ARGAN SPRAY ADRIANGEL X 50 ML | C10: ADRIANGEL | D10: 32000
B11: ACEITE DE CAFE VERDE ADRIANGEL X 120 ML | C11: ADRIANGEL | D11: 15000
B12: ACEITE DE CALENDULA ADRIANGEL X 120 ML | C12: ADRIANGEL | D12: 15000
B13: ACEITE DE CANELA ADRIANGEL X 120 ML | C13: ADRIANGEL | D13: 15000
B14: ACEITE DE COCO ADRIANGEL X 120 ML | C14: ADRIANGEL | D14: 15000
B15: ACEITE DE EUCALIPTO ADRIANGEL X 120 ML | C15: ADRIANGEL | D15: 15000
B16: ACEITE DE GERMEN DE TRIGO ADRIANGEL X 120 ML | C16: ADRIANGEL | D16: 15000
B17: ACEITE DE GIRASOL ADRIANGEL X 120 ML | C17: ADRIANGEL | D17: 15000
B18: ACEITE DE JOJOBA ADRIANGEL X 120 ML | C18: ADRIANGEL | D18: 15000
... B533: VITAMINA E 1000 UI + SELENIO IMPORTADO FARNAT BLISTER X 30 SOFTGELS | C533: VARIOS | D533: 29000
B536: PRODUCTO A DESCODIFICAR
B537: PRODUCTO SIN REGISTRO
